{"level":"ERROR","location":"[On_message:1443] data_ws","message":"'ltp'","timestamp":"2024-05-15 00:14:32,922+0530","service":"FyersDataSocket","exception":"Traceback (most recent call last):\n  File \"C:\\Users\\aryan\\AppData\\Local\\Programs\\Python\\Python311\\Lib\\site-packages\\fyers_apiv3\\FyersWebsocket\\data_ws.py\", line 1434, in On_message\n    self.OnMessage(message)\n  File \"c:\\Users\\aryan\\Desktop\\FYRES\\socket_dat.py\", line 20, in onmessage\n    price=message['ltp']\n          ~~~~~~~^^^^^^^\nKeyError: 'ltp'","exception_name":"KeyError"}
{"level":"ERROR","location":"[On_message:1443] data_ws","message":"'ltp'","timestamp":"2024-05-15 00:14:43,475+0530","service":"FyersDataSocket","exception":"Traceback (most recent call last):\n  File \"C:\\Users\\aryan\\AppData\\Local\\Programs\\Python\\Python311\\Lib\\site-packages\\fyers_apiv3\\FyersWebsocket\\data_ws.py\", line 1434, in On_message\n    self.OnMessage(message)\n  File \"c:\\Users\\aryan\\Desktop\\FYRES\\socket_dat.py\", line 20, in onmessage\n    price=message['ltp']\n          ~~~~~~~^^^^^^^\nKeyError: 'ltp'","exception_name":"KeyError"}
{"level":"ERROR","location":"[On_message:1443] data_ws","message":"'ltp'","timestamp":"2024-05-15 00:14:43,479+0530","service":"FyersDataSocket","exception":"Traceback (most recent call last):\n  File \"C:\\Users\\aryan\\AppData\\Local\\Programs\\Python\\Python311\\Lib\\site-packages\\fyers_apiv3\\FyersWebsocket\\data_ws.py\", line 1434, in On_message\n    self.OnMessage(message)\n  File \"c:\\Users\\aryan\\Desktop\\FYRES\\socket_dat.py\", line 20, in onmessage\n    price=message['ltp']\n          ~~~~~~~^^^^^^^\nKeyError: 'ltp'","exception_name":"KeyError"}
{"level":"ERROR","location":"[On_message:1443] data_ws","message":"'ltp'","timestamp":"2024-05-15 00:14:43,483+0530","service":"FyersDataSocket","exception":"Traceback (most recent call last):\n  File \"C:\\Users\\aryan\\AppData\\Local\\Programs\\Python\\Python311\\Lib\\site-packages\\fyers_apiv3\\FyersWebsocket\\data_ws.py\", line 1434, in On_message\n    self.OnMessage(message)\n  File \"c:\\Users\\aryan\\Desktop\\FYRES\\socket_dat.py\", line 20, in onmessage\n    price=message['ltp']\n          ~~~~~~~^^^^^^^\nKeyError: 'ltp'","exception_name":"KeyError"}
{"level":"ERROR","location":"[On_message:1443] data_ws","message":"'ltp'","timestamp":"2024-05-15 00:29:04,696+0530","service":"FyersDataSocket","exception":"Traceback (most recent call last):\n  File \"C:\\Users\\aryan\\AppData\\Local\\Programs\\Python\\Python311\\Lib\\site-packages\\fyers_apiv3\\FyersWebsocket\\data_ws.py\", line 1434, in On_message\n    self.OnMessage(message)\n  File \"c:\\Users\\aryan\\Desktop\\FYRES\\socket_dat.py\", line 20, in onmessage\n    price=print(\"ltp\",message['ltp'])\n                      ~~~~~~~^^^^^^^\nKeyError: 'ltp'","exception_name":"KeyError"}
{"level":"ERROR","location":"[On_message:1443] data_ws","message":"'ltp'","timestamp":"2024-05-15 00:29:05,150+0530","service":"FyersDataSocket","exception":"Traceback (most recent call last):\n  File \"C:\\Users\\aryan\\AppData\\Local\\Programs\\Python\\Python311\\Lib\\site-packages\\fyers_apiv3\\FyersWebsocket\\data_ws.py\", line 1434, in On_message\n    self.OnMessage(message)\n  File \"c:\\Users\\aryan\\Desktop\\FYRES\\socket_dat.py\", line 20, in onmessage\n    price=print(\"ltp\",message['ltp'])\n                      ~~~~~~~^^^^^^^\nKeyError: 'ltp'","exception_name":"KeyError"}
{"level":"ERROR","location":"[On_message:1443] data_ws","message":"'ltp'","timestamp":"2024-05-15 00:29:06,124+0530","service":"FyersDataSocket","exception":"Traceback (most recent call last):\n  File \"C:\\Users\\aryan\\AppData\\Local\\Programs\\Python\\Python311\\Lib\\site-packages\\fyers_apiv3\\FyersWebsocket\\data_ws.py\", line 1434, in On_message\n    self.OnMessage(message)\n  File \"c:\\Users\\aryan\\Desktop\\FYRES\\socket_dat.py\", line 20, in onmessage\n    price=print(\"ltp\",message['ltp'])\n                      ~~~~~~~^^^^^^^\nKeyError: 'ltp'","exception_name":"KeyError"}
{"level":"ERROR","location":"[On_message:1443] data_ws","message":"'ltp'","timestamp":"2024-05-15 00:29:06,998+0530","service":"FyersDataSocket","exception":"Traceback (most recent call last):\n  File \"C:\\Users\\aryan\\AppData\\Local\\Programs\\Python\\Python311\\Lib\\site-packages\\fyers_apiv3\\FyersWebsocket\\data_ws.py\", line 1434, in On_message\n    self.OnMessage(message)\n  File \"c:\\Users\\aryan\\Desktop\\FYRES\\socket_dat.py\", line 20, in onmessage\n    price=print(\"ltp\",message['ltp'])\n                      ~~~~~~~^^^^^^^\nKeyError: 'ltp'","exception_name":"KeyError"}
{"level":"ERROR","location":"[On_message:1443] data_ws","message":"'ltp'","timestamp":"2024-05-15 00:30:32,794+0530","service":"FyersDataSocket","exception":"Traceback (most recent call last):\n  File \"C:\\Users\\aryan\\AppData\\Local\\Programs\\Python\\Python311\\Lib\\site-packages\\fyers_apiv3\\FyersWebsocket\\data_ws.py\", line 1434, in On_message\n    self.OnMessage(message)\n  File \"c:\\Users\\aryan\\Desktop\\FYRES\\socket_dat.py\", line 20, in onmessage\n    price=print(\"ltp\",message['ltp'])\n                      ~~~~~~~^^^^^^^\nKeyError: 'ltp'","exception_name":"KeyError"}
{"level":"ERROR","location":"[On_message:1443] data_ws","message":"'ltp'","timestamp":"2024-05-15 00:30:33,799+0530","service":"FyersDataSocket","exception":"Traceback (most recent call last):\n  File \"C:\\Users\\aryan\\AppData\\Local\\Programs\\Python\\Python311\\Lib\\site-packages\\fyers_apiv3\\FyersWebsocket\\data_ws.py\", line 1434, in On_message\n    self.OnMessage(message)\n  File \"c:\\Users\\aryan\\Desktop\\FYRES\\socket_dat.py\", line 20, in onmessage\n    price=print(\"ltp\",message['ltp'])\n                      ~~~~~~~^^^^^^^\nKeyError: 'ltp'","exception_name":"KeyError"}
{"level":"ERROR","location":"[On_message:1443] data_ws","message":"'ltp'","timestamp":"2024-05-15 00:30:33,814+0530","service":"FyersDataSocket","exception":"Traceback (most recent call last):\n  File \"C:\\Users\\aryan\\AppData\\Local\\Programs\\Python\\Python311\\Lib\\site-packages\\fyers_apiv3\\FyersWebsocket\\data_ws.py\", line 1434, in On_message\n    self.OnMessage(message)\n  File \"c:\\Users\\aryan\\Desktop\\FYRES\\socket_dat.py\", line 20, in onmessage\n    price=print(\"ltp\",message['ltp'])\n                      ~~~~~~~^^^^^^^\nKeyError: 'ltp'","exception_name":"KeyError"}
{"level":"ERROR","location":"[On_message:1443] data_ws","message":"'ltp'","timestamp":"2024-05-15 00:30:34,667+0530","service":"FyersDataSocket","exception":"Traceback (most recent call last):\n  File \"C:\\Users\\aryan\\AppData\\Local\\Programs\\Python\\Python311\\Lib\\site-packages\\fyers_apiv3\\FyersWebsocket\\data_ws.py\", line 1434, in On_message\n    self.OnMessage(message)\n  File \"c:\\Users\\aryan\\Desktop\\FYRES\\socket_dat.py\", line 20, in onmessage\n    price=print(\"ltp\",message['ltp'])\n                      ~~~~~~~^^^^^^^\nKeyError: 'ltp'","exception_name":"KeyError"}
{"level":"ERROR","location":"[On_message:1443] data_ws","message":"'ltp'","timestamp":"2024-05-15 00:40:18,346+0530","service":"FyersDataSocket","exception":"Traceback (most recent call last):\n  File \"C:\\Users\\aryan\\AppData\\Local\\Programs\\Python\\Python311\\Lib\\site-packages\\fyers_apiv3\\FyersWebsocket\\data_ws.py\", line 1434, in On_message\n    self.OnMessage(message)\n  File \"c:\\Users\\aryan\\Desktop\\FYRES\\socket_dat.py\", line 20, in onmessage\n    price=print(\"ltp\",message['ltp'])\n                      ~~~~~~~^^^^^^^\nKeyError: 'ltp'","exception_name":"KeyError"}
{"level":"ERROR","location":"[On_message:1443] data_ws","message":"'ltp'","timestamp":"2024-05-15 00:40:24,772+0530","service":"FyersDataSocket","exception":"Traceback (most recent call last):\n  File \"C:\\Users\\aryan\\AppData\\Local\\Programs\\Python\\Python311\\Lib\\site-packages\\fyers_apiv3\\FyersWebsocket\\data_ws.py\", line 1434, in On_message\n    self.OnMessage(message)\n  File \"c:\\Users\\aryan\\Desktop\\FYRES\\socket_dat.py\", line 20, in onmessage\n    price=print(\"ltp\",message['ltp'])\n                      ~~~~~~~^^^^^^^\nKeyError: 'ltp'","exception_name":"KeyError"}
{"level":"ERROR","location":"[On_message:1443] data_ws","message":"'ltp'","timestamp":"2024-05-15 00:43:17,623+0530","service":"FyersDataSocket","exception":"Traceback (most recent call last):\n  File \"C:\\Users\\aryan\\AppData\\Local\\Programs\\Python\\Python311\\Lib\\site-packages\\fyers_apiv3\\FyersWebsocket\\data_ws.py\", line 1434, in On_message\n    self.OnMessage(message)\n  File \"c:\\Users\\aryan\\Desktop\\FYRES\\socket_dat.py\", line 20, in onmessage\n    price=print(\"ltp\",message['ltp'])\n                      ~~~~~~~^^^^^^^\nKeyError: 'ltp'","exception_name":"KeyError"}
{"level":"ERROR","location":"[On_message:1443] data_ws","message":"'ltp'","timestamp":"2024-05-15 00:43:20,011+0530","service":"FyersDataSocket","exception":"Traceback (most recent call last):\n  File \"C:\\Users\\aryan\\AppData\\Local\\Programs\\Python\\Python311\\Lib\\site-packages\\fyers_apiv3\\FyersWebsocket\\data_ws.py\", line 1434, in On_message\n    self.OnMessage(message)\n  File \"c:\\Users\\aryan\\Desktop\\FYRES\\socket_dat.py\", line 20, in onmessage\n    price=print(\"ltp\",message['ltp'])\n                      ~~~~~~~^^^^^^^\nKeyError: 'ltp'","exception_name":"KeyError"}
{"level":"ERROR","location":"[On_message:1443] data_ws","message":"'ltp'","timestamp":"2024-05-15 00:43:20,078+0530","service":"FyersDataSocket","exception":"Traceback (most recent call last):\n  File \"C:\\Users\\aryan\\AppData\\Local\\Programs\\Python\\Python311\\Lib\\site-packages\\fyers_apiv3\\FyersWebsocket\\data_ws.py\", line 1434, in On_message\n    self.OnMessage(message)\n  File \"c:\\Users\\aryan\\Desktop\\FYRES\\socket_dat.py\", line 20, in onmessage\n    price=print(\"ltp\",message['ltp'])\n                      ~~~~~~~^^^^^^^\nKeyError: 'ltp'","exception_name":"KeyError"}
{"level":"ERROR","location":"[On_message:1443] data_ws","message":"'ltp'","timestamp":"2024-05-15 00:43:20,113+0530","service":"FyersDataSocket","exception":"Traceback (most recent call last):\n  File \"C:\\Users\\aryan\\AppData\\Local\\Programs\\Python\\Python311\\Lib\\site-packages\\fyers_apiv3\\FyersWebsocket\\data_ws.py\", line 1434, in On_message\n    self.OnMessage(message)\n  File \"c:\\Users\\aryan\\Desktop\\FYRES\\socket_dat.py\", line 20, in onmessage\n    price=print(\"ltp\",message['ltp'])\n                      ~~~~~~~^^^^^^^\nKeyError: 'ltp'","exception_name":"KeyError"}
{"level":"ERROR","location":"[On_message:1443] data_ws","message":"'ltp'","timestamp":"2024-05-15 00:43:22,877+0530","service":"FyersDataSocket","exception":"Traceback (most recent call last):\n  File \"C:\\Users\\aryan\\AppData\\Local\\Programs\\Python\\Python311\\Lib\\site-packages\\fyers_apiv3\\FyersWebsocket\\data_ws.py\", line 1434, in On_message\n    self.OnMessage(message)\n  File \"c:\\Users\\aryan\\Desktop\\FYRES\\socket_dat.py\", line 20, in onmessage\n    price=print(\"ltp\",message['ltp'])\n                      ~~~~~~~^^^^^^^\nKeyError: 'ltp'","exception_name":"KeyError"}
{"level":"ERROR","location":"[On_message:1443] data_ws","message":"'ltp'","timestamp":"2024-05-15 00:43:22,915+0530","service":"FyersDataSocket","exception":"Traceback (most recent call last):\n  File \"C:\\Users\\aryan\\AppData\\Local\\Programs\\Python\\Python311\\Lib\\site-packages\\fyers_apiv3\\FyersWebsocket\\data_ws.py\", line 1434, in On_message\n    self.OnMessage(message)\n  File \"c:\\Users\\aryan\\Desktop\\FYRES\\socket_dat.py\", line 20, in onmessage\n    price=print(\"ltp\",message['ltp'])\n                      ~~~~~~~^^^^^^^\nKeyError: 'ltp'","exception_name":"KeyError"}
{"level":"ERROR","location":"[On_message:1443] data_ws","message":"'ltp'","timestamp":"2024-05-15 00:44:19,040+0530","service":"FyersDataSocket","exception":"Traceback (most recent call last):\n  File \"C:\\Users\\aryan\\AppData\\Local\\Programs\\Python\\Python311\\Lib\\site-packages\\fyers_apiv3\\FyersWebsocket\\data_ws.py\", line 1434, in On_message\n    self.OnMessage(message)\n  File \"c:\\Users\\aryan\\Desktop\\FYRES\\socket_dat.py\", line 20, in onmessage\n    price=print(\"ltp\",message['ltp'])\n                      ~~~~~~~^^^^^^^\nKeyError: 'ltp'","exception_name":"KeyError"}
{"level":"ERROR","location":"[On_message:1443] data_ws","message":"'ltp'","timestamp":"2024-05-15 00:44:19,683+0530","service":"FyersDataSocket","exception":"Traceback (most recent call last):\n  File \"C:\\Users\\aryan\\AppData\\Local\\Programs\\Python\\Python311\\Lib\\site-packages\\fyers_apiv3\\FyersWebsocket\\data_ws.py\", line 1434, in On_message\n    self.OnMessage(message)\n  File \"c:\\Users\\aryan\\Desktop\\FYRES\\socket_dat.py\", line 20, in onmessage\n    price=print(\"ltp\",message['ltp'])\n                      ~~~~~~~^^^^^^^\nKeyError: 'ltp'","exception_name":"KeyError"}
{"level":"ERROR","location":"[On_message:1443] data_ws","message":"'ltp'","timestamp":"2024-05-15 00:44:19,683+0530","service":"FyersDataSocket","exception":"Traceback (most recent call last):\n  File \"C:\\Users\\aryan\\AppData\\Local\\Programs\\Python\\Python311\\Lib\\site-packages\\fyers_apiv3\\FyersWebsocket\\data_ws.py\", line 1434, in On_message\n    self.OnMessage(message)\n  File \"c:\\Users\\aryan\\Desktop\\FYRES\\socket_dat.py\", line 20, in onmessage\n    price=print(\"ltp\",message['ltp'])\n                      ~~~~~~~^^^^^^^\nKeyError: 'ltp'","exception_name":"KeyError"}
{"level":"ERROR","location":"[On_message:1443] data_ws","message":"'ltp'","timestamp":"2024-05-15 00:44:19,694+0530","service":"FyersDataSocket","exception":"Traceback (most recent call last):\n  File \"C:\\Users\\aryan\\AppData\\Local\\Programs\\Python\\Python311\\Lib\\site-packages\\fyers_apiv3\\FyersWebsocket\\data_ws.py\", line 1434, in On_message\n    self.OnMessage(message)\n  File \"c:\\Users\\aryan\\Desktop\\FYRES\\socket_dat.py\", line 20, in onmessage\n    price=print(\"ltp\",message['ltp'])\n                      ~~~~~~~^^^^^^^\nKeyError: 'ltp'","exception_name":"KeyError"}
{"level":"ERROR","location":"[On_message:1443] data_ws","message":"'ltp'","timestamp":"2024-05-15 00:44:19,696+0530","service":"FyersDataSocket","exception":"Traceback (most recent call last):\n  File \"C:\\Users\\aryan\\AppData\\Local\\Programs\\Python\\Python311\\Lib\\site-packages\\fyers_apiv3\\FyersWebsocket\\data_ws.py\", line 1434, in On_message\n    self.OnMessage(message)\n  File \"c:\\Users\\aryan\\Desktop\\FYRES\\socket_dat.py\", line 20, in onmessage\n    price=print(\"ltp\",message['ltp'])\n                      ~~~~~~~^^^^^^^\nKeyError: 'ltp'","exception_name":"KeyError"}
{"level":"ERROR","location":"[On_message:1443] data_ws","message":"'ltp'","timestamp":"2024-05-15 00:45:30,641+0530","service":"FyersDataSocket","exception":"Traceback (most recent call last):\n  File \"C:\\Users\\aryan\\AppData\\Local\\Programs\\Python\\Python311\\Lib\\site-packages\\fyers_apiv3\\FyersWebsocket\\data_ws.py\", line 1434, in On_message\n    self.OnMessage(message)\n  File \"c:\\Users\\aryan\\Desktop\\FYRES\\socket_dat.py\", line 20, in onmessage\n    price=print(\"ltp\",message['ltp'])\n                      ~~~~~~~^^^^^^^\nKeyError: 'ltp'","exception_name":"KeyError"}
{"level":"ERROR","location":"[On_message:1443] data_ws","message":"'ltp'","timestamp":"2024-05-15 00:45:36,789+0530","service":"FyersDataSocket","exception":"Traceback (most recent call last):\n  File \"C:\\Users\\aryan\\AppData\\Local\\Programs\\Python\\Python311\\Lib\\site-packages\\fyers_apiv3\\FyersWebsocket\\data_ws.py\", line 1434, in On_message\n    self.OnMessage(message)\n  File \"c:\\Users\\aryan\\Desktop\\FYRES\\socket_dat.py\", line 20, in onmessage\n    price=print(\"ltp\",message['ltp'])\n                      ~~~~~~~^^^^^^^\nKeyError: 'ltp'","exception_name":"KeyError"}
{"level":"ERROR","location":"[On_message:1443] data_ws","message":"'ltp'","timestamp":"2024-05-15 00:45:39,993+0530","service":"FyersDataSocket","exception":"Traceback (most recent call last):\n  File \"C:\\Users\\aryan\\AppData\\Local\\Programs\\Python\\Python311\\Lib\\site-packages\\fyers_apiv3\\FyersWebsocket\\data_ws.py\", line 1434, in On_message\n    self.OnMessage(message)\n  File \"c:\\Users\\aryan\\Desktop\\FYRES\\socket_dat.py\", line 20, in onmessage\n    price=print(\"ltp\",message['ltp'])\n                      ~~~~~~~^^^^^^^\nKeyError: 'ltp'","exception_name":"KeyError"}
{"level":"ERROR","location":"[On_message:1443] data_ws","message":"'ltp'","timestamp":"2024-05-15 00:45:40,659+0530","service":"FyersDataSocket","exception":"Traceback (most recent call last):\n  File \"C:\\Users\\aryan\\AppData\\Local\\Programs\\Python\\Python311\\Lib\\site-packages\\fyers_apiv3\\FyersWebsocket\\data_ws.py\", line 1434, in On_message\n    self.OnMessage(message)\n  File \"c:\\Users\\aryan\\Desktop\\FYRES\\socket_dat.py\", line 20, in onmessage\n    price=print(\"ltp\",message['ltp'])\n                      ~~~~~~~^^^^^^^\nKeyError: 'ltp'","exception_name":"KeyError"}
{"level":"ERROR","location":"[On_message:1443] data_ws","message":"'ltp'","timestamp":"2024-05-15 00:45:42,650+0530","service":"FyersDataSocket","exception":"Traceback (most recent call last):\n  File \"C:\\Users\\aryan\\AppData\\Local\\Programs\\Python\\Python311\\Lib\\site-packages\\fyers_apiv3\\FyersWebsocket\\data_ws.py\", line 1434, in On_message\n    self.OnMessage(message)\n  File \"c:\\Users\\aryan\\Desktop\\FYRES\\socket_dat.py\", line 20, in onmessage\n    price=print(\"ltp\",message['ltp'])\n                      ~~~~~~~^^^^^^^\nKeyError: 'ltp'","exception_name":"KeyError"}
{"level":"ERROR","location":"[On_message:1443] data_ws","message":"'ltp'","timestamp":"2024-05-15 00:45:42,768+0530","service":"FyersDataSocket","exception":"Traceback (most recent call last):\n  File \"C:\\Users\\aryan\\AppData\\Local\\Programs\\Python\\Python311\\Lib\\site-packages\\fyers_apiv3\\FyersWebsocket\\data_ws.py\", line 1434, in On_message\n    self.OnMessage(message)\n  File \"c:\\Users\\aryan\\Desktop\\FYRES\\socket_dat.py\", line 20, in onmessage\n    price=print(\"ltp\",message['ltp'])\n                      ~~~~~~~^^^^^^^\nKeyError: 'ltp'","exception_name":"KeyError"}
{"level":"ERROR","location":"[On_message:1443] data_ws","message":"'ltp'","timestamp":"2024-05-15 00:47:42,226+0530","service":"FyersDataSocket","exception":"Traceback (most recent call last):\n  File \"C:\\Users\\aryan\\AppData\\Local\\Programs\\Python\\Python311\\Lib\\site-packages\\fyers_apiv3\\FyersWebsocket\\data_ws.py\", line 1434, in On_message\n    self.OnMessage(message)\n  File \"c:\\Users\\aryan\\Desktop\\FYRES\\socket_dat.py\", line 20, in onmessage\n    price=print(\"ltp\",message['ltp'])\n                      ~~~~~~~^^^^^^^\nKeyError: 'ltp'","exception_name":"KeyError"}
{"level":"ERROR","location":"[On_message:1443] data_ws","message":"'ltp'","timestamp":"2024-05-15 00:47:43,778+0530","service":"FyersDataSocket","exception":"Traceback (most recent call last):\n  File \"C:\\Users\\aryan\\AppData\\Local\\Programs\\Python\\Python311\\Lib\\site-packages\\fyers_apiv3\\FyersWebsocket\\data_ws.py\", line 1434, in On_message\n    self.OnMessage(message)\n  File \"c:\\Users\\aryan\\Desktop\\FYRES\\socket_dat.py\", line 20, in onmessage\n    price=print(\"ltp\",message['ltp'])\n                      ~~~~~~~^^^^^^^\nKeyError: 'ltp'","exception_name":"KeyError"}
{"level":"ERROR","location":"[symbol_to_hsmtoken:127] data_ws","message":"cannot access local variable 'hsm_symbol' where it is not associated with a value","timestamp":"2024-05-15 00:47:43,989+0530","service":"FyersDataSocket","exception":"Traceback (most recent call last):\n  File \"C:\\Users\\aryan\\AppData\\Local\\Programs\\Python\\Python311\\Lib\\site-packages\\fyers_apiv3\\FyersWebsocket\\data_ws.py\", line 115, in symbol_to_hsmtoken\n    datadict[hsm_symbol] = symbol\n             ^^^^^^^^^^\nUnboundLocalError: cannot access local variable 'hsm_symbol' where it is not associated with a value","exception_name":"UnboundLocalError"}
{"level":"ERROR","location":"[__symbol_conversion:1375] data_ws","message":"'NoneType' object is not subscriptable","timestamp":"2024-05-15 00:47:43,989+0530","service":"FyersDataSocket","exception":"Traceback (most recent call last):\n  File \"C:\\Users\\aryan\\AppData\\Local\\Programs\\Python\\Python311\\Lib\\site-packages\\fyers_apiv3\\FyersWebsocket\\data_ws.py\", line 1334, in __symbol_conversion\n    if symbol_value[3] != \"\":\n       ~~~~~~~~~~~~^^^\nTypeError: 'NoneType' object is not subscriptable","exception_name":"TypeError"}
{"level":"ERROR","location":"[symbol_to_hsmtoken:127] data_ws","message":"cannot access local variable 'hsm_symbol' where it is not associated with a value","timestamp":"2024-05-15 00:47:44,337+0530","service":"FyersDataSocket","exception":"Traceback (most recent call last):\n  File \"C:\\Users\\aryan\\AppData\\Local\\Programs\\Python\\Python311\\Lib\\site-packages\\fyers_apiv3\\FyersWebsocket\\data_ws.py\", line 115, in symbol_to_hsmtoken\n    datadict[hsm_symbol] = symbol\n             ^^^^^^^^^^\nUnboundLocalError: cannot access local variable 'hsm_symbol' where it is not associated with a value","exception_name":"UnboundLocalError"}
{"level":"ERROR","location":"[__symbol_conversion:1375] data_ws","message":"'NoneType' object is not subscriptable","timestamp":"2024-05-15 00:47:44,352+0530","service":"FyersDataSocket","exception":"Traceback (most recent call last):\n  File \"C:\\Users\\aryan\\AppData\\Local\\Programs\\Python\\Python311\\Lib\\site-packages\\fyers_apiv3\\FyersWebsocket\\data_ws.py\", line 1334, in __symbol_conversion\n    if symbol_value[3] != \"\":\n       ~~~~~~~~~~~~^^^\nTypeError: 'NoneType' object is not subscriptable","exception_name":"TypeError"}
{"level":"ERROR","location":"[On_message:1443] data_ws","message":"'vol_traded_today'","timestamp":"2024-05-15 00:50:02,015+0530","service":"FyersDataSocket","exception":"Traceback (most recent call last):\n  File \"C:\\Users\\aryan\\AppData\\Local\\Programs\\Python\\Python311\\Lib\\site-packages\\fyers_apiv3\\FyersWebsocket\\data_ws.py\", line 1434, in On_message\n    self.OnMessage(message)\n  File \"c:\\Users\\aryan\\Desktop\\FYRES\\socket_dat.py\", line 21, in onmessage\n    vol=message['vol_traded_today']\n        ~~~~~~~^^^^^^^^^^^^^^^^^^^^\nKeyError: 'vol_traded_today'","exception_name":"KeyError"}
{"level":"ERROR","location":"[On_message:1443] data_ws","message":"'vol_traded_today'","timestamp":"2024-05-15 00:50:02,884+0530","service":"FyersDataSocket","exception":"Traceback (most recent call last):\n  File \"C:\\Users\\aryan\\AppData\\Local\\Programs\\Python\\Python311\\Lib\\site-packages\\fyers_apiv3\\FyersWebsocket\\data_ws.py\", line 1434, in On_message\n    self.OnMessage(message)\n  File \"c:\\Users\\aryan\\Desktop\\FYRES\\socket_dat.py\", line 21, in onmessage\n    vol=message['vol_traded_today']\n        ~~~~~~~^^^^^^^^^^^^^^^^^^^^\nKeyError: 'vol_traded_today'","exception_name":"KeyError"}
{"level":"ERROR","location":"[On_message:1443] data_ws","message":"'vol_traded_today'","timestamp":"2024-05-15 00:50:04,285+0530","service":"FyersDataSocket","exception":"Traceback (most recent call last):\n  File \"C:\\Users\\aryan\\AppData\\Local\\Programs\\Python\\Python311\\Lib\\site-packages\\fyers_apiv3\\FyersWebsocket\\data_ws.py\", line 1434, in On_message\n    self.OnMessage(message)\n  File \"c:\\Users\\aryan\\Desktop\\FYRES\\socket_dat.py\", line 21, in onmessage\n    vol=message['vol_traded_today']\n        ~~~~~~~^^^^^^^^^^^^^^^^^^^^\nKeyError: 'vol_traded_today'","exception_name":"KeyError"}
{"level":"ERROR","location":"[On_message:1443] data_ws","message":"'vol_traded_today'","timestamp":"2024-05-15 00:50:04,368+0530","service":"FyersDataSocket","exception":"Traceback (most recent call last):\n  File \"C:\\Users\\aryan\\AppData\\Local\\Programs\\Python\\Python311\\Lib\\site-packages\\fyers_apiv3\\FyersWebsocket\\data_ws.py\", line 1434, in On_message\n    self.OnMessage(message)\n  File \"c:\\Users\\aryan\\Desktop\\FYRES\\socket_dat.py\", line 21, in onmessage\n    vol=message['vol_traded_today']\n        ~~~~~~~^^^^^^^^^^^^^^^^^^^^\nKeyError: 'vol_traded_today'","exception_name":"KeyError"}
{"level":"ERROR","location":"[On_message:1443] data_ws","message":"'vol_traded_today'","timestamp":"2024-05-15 00:50:05,139+0530","service":"FyersDataSocket","exception":"Traceback (most recent call last):\n  File \"C:\\Users\\aryan\\AppData\\Local\\Programs\\Python\\Python311\\Lib\\site-packages\\fyers_apiv3\\FyersWebsocket\\data_ws.py\", line 1434, in On_message\n    self.OnMessage(message)\n  File \"c:\\Users\\aryan\\Desktop\\FYRES\\socket_dat.py\", line 21, in onmessage\n    vol=message['vol_traded_today']\n        ~~~~~~~^^^^^^^^^^^^^^^^^^^^\nKeyError: 'vol_traded_today'","exception_name":"KeyError"}
{"level":"ERROR","location":"[On_message:1443] data_ws","message":"'vol_traded_today'","timestamp":"2024-05-15 00:50:05,165+0530","service":"FyersDataSocket","exception":"Traceback (most recent call last):\n  File \"C:\\Users\\aryan\\AppData\\Local\\Programs\\Python\\Python311\\Lib\\site-packages\\fyers_apiv3\\FyersWebsocket\\data_ws.py\", line 1434, in On_message\n    self.OnMessage(message)\n  File \"c:\\Users\\aryan\\Desktop\\FYRES\\socket_dat.py\", line 21, in onmessage\n    vol=message['vol_traded_today']\n        ~~~~~~~^^^^^^^^^^^^^^^^^^^^\nKeyError: 'vol_traded_today'","exception_name":"KeyError"}
{"level":"ERROR","location":"[On_message:1443] data_ws","message":"'vol_traded_today'","timestamp":"2024-05-15 00:58:57,945+0530","service":"FyersDataSocket","exception":"Traceback (most recent call last):\n  File \"C:\\Users\\aryan\\AppData\\Local\\Programs\\Python\\Python311\\Lib\\site-packages\\fyers_apiv3\\FyersWebsocket\\data_ws.py\", line 1434, in On_message\n    self.OnMessage(message)\n  File \"c:\\Users\\aryan\\Desktop\\FYRES\\socket_dat.py\", line 21, in onmessage\n    vol=message['vol_traded_today']\n        ~~~~~~~^^^^^^^^^^^^^^^^^^^^\nKeyError: 'vol_traded_today'","exception_name":"KeyError"}
{"level":"ERROR","location":"[On_message:1443] data_ws","message":"'vol_traded_today'","timestamp":"2024-05-15 00:58:59,375+0530","service":"FyersDataSocket","exception":"Traceback (most recent call last):\n  File \"C:\\Users\\aryan\\AppData\\Local\\Programs\\Python\\Python311\\Lib\\site-packages\\fyers_apiv3\\FyersWebsocket\\data_ws.py\", line 1434, in On_message\n    self.OnMessage(message)\n  File \"c:\\Users\\aryan\\Desktop\\FYRES\\socket_dat.py\", line 21, in onmessage\n    vol=message['vol_traded_today']\n        ~~~~~~~^^^^^^^^^^^^^^^^^^^^\nKeyError: 'vol_traded_today'","exception_name":"KeyError"}
{"level":"ERROR","location":"[On_message:1443] data_ws","message":"'vol_traded_today'","timestamp":"2024-05-15 00:59:00,255+0530","service":"FyersDataSocket","exception":"Traceback (most recent call last):\n  File \"C:\\Users\\aryan\\AppData\\Local\\Programs\\Python\\Python311\\Lib\\site-packages\\fyers_apiv3\\FyersWebsocket\\data_ws.py\", line 1434, in On_message\n    self.OnMessage(message)\n  File \"c:\\Users\\aryan\\Desktop\\FYRES\\socket_dat.py\", line 21, in onmessage\n    vol=message['vol_traded_today']\n        ~~~~~~~^^^^^^^^^^^^^^^^^^^^\nKeyError: 'vol_traded_today'","exception_name":"KeyError"}
{"level":"ERROR","location":"[On_message:1443] data_ws","message":"'vol_traded_today'","timestamp":"2024-05-15 00:59:00,288+0530","service":"FyersDataSocket","exception":"Traceback (most recent call last):\n  File \"C:\\Users\\aryan\\AppData\\Local\\Programs\\Python\\Python311\\Lib\\site-packages\\fyers_apiv3\\FyersWebsocket\\data_ws.py\", line 1434, in On_message\n    self.OnMessage(message)\n  File \"c:\\Users\\aryan\\Desktop\\FYRES\\socket_dat.py\", line 21, in onmessage\n    vol=message['vol_traded_today']\n        ~~~~~~~^^^^^^^^^^^^^^^^^^^^\nKeyError: 'vol_traded_today'","exception_name":"KeyError"}
{"level":"ERROR","location":"[symbol_to_hsmtoken:127] data_ws","message":"HTTPSConnectionPool(host='api-t1.fyers.in', port=443): Max retries exceeded with url: /data/symbol-token (Caused by NameResolutionError(\"<urllib3.connection.HTTPSConnection object at 0x00000274A3EAC0D0>: Failed to resolve 'api-t1.fyers.in' ([Errno 11001] getaddrinfo failed)\"))","timestamp":"2024-05-15 02:19:04,645+0530","service":"FyersDataSocket","exception":"Traceback (most recent call last):\n  File \"C:\\Users\\aryan\\AppData\\Local\\Programs\\Python\\Python311\\Lib\\site-packages\\websocket\\_app.py\", line 428, in setSock\n    dispatcher.read(self.sock.sock, read, check)\n  File \"C:\\Users\\aryan\\AppData\\Local\\Programs\\Python\\Python311\\Lib\\site-packages\\websocket\\_app.py\", line 99, in read\n    if not read_callback():\n           ^^^^^^^^^^^^^^^\n  File \"C:\\Users\\aryan\\AppData\\Local\\Programs\\Python\\Python311\\Lib\\site-packages\\websocket\\_app.py\", line 442, in read\n    raise e\n  File \"C:\\Users\\aryan\\AppData\\Local\\Programs\\Python\\Python311\\Lib\\site-packages\\websocket\\_app.py\", line 437, in read\n    op_code, frame = self.sock.recv_data_frame(True)\n                     ^^^^^^^^^^^^^^^^^^^^^^^^^^^^^^^\n  File \"C:\\Users\\aryan\\AppData\\Local\\Programs\\Python\\Python311\\Lib\\site-packages\\websocket\\_core.py\", line 406, in recv_data_frame\n    frame = self.recv_frame()\n            ^^^^^^^^^^^^^^^^^\n  File \"C:\\Users\\aryan\\AppData\\Local\\Programs\\Python\\Python311\\Lib\\site-packages\\websocket\\_core.py\", line 445, in recv_frame\n    return self.frame_buffer.recv_frame()\n           ^^^^^^^^^^^^^^^^^^^^^^^^^^^^^^\n  File \"C:\\Users\\aryan\\AppData\\Local\\Programs\\Python\\Python311\\Lib\\site-packages\\websocket\\_abnf.py\", line 338, in recv_frame\n    self.recv_header()\n  File \"C:\\Users\\aryan\\AppData\\Local\\Programs\\Python\\Python311\\Lib\\site-packages\\websocket\\_abnf.py\", line 294, in recv_header\n    header = self.recv_strict(2)\n             ^^^^^^^^^^^^^^^^^^^\n  File \"C:\\Users\\aryan\\AppData\\Local\\Programs\\Python\\Python311\\Lib\\site-packages\\websocket\\_abnf.py\", line 373, in recv_strict\n    bytes_ = self.recv(min(16384, shortage))\n             ^^^^^^^^^^^^^^^^^^^^^^^^^^^^^^^\n  File \"C:\\Users\\aryan\\AppData\\Local\\Programs\\Python\\Python311\\Lib\\site-packages\\websocket\\_core.py\", line 529, in _recv\n    return recv(self.sock, bufsize)\n           ^^^^^^^^^^^^^^^^^^^^^^^^\n  File \"C:\\Users\\aryan\\AppData\\Local\\Programs\\Python\\Python311\\Lib\\site-packages\\websocket\\_socket.py\", line 122, in recv\n    raise WebSocketConnectionClosedException(\nwebsocket._exceptions.WebSocketConnectionClosedException: Connection to remote host was lost.\n\nDuring handling of the above exception, another exception occurred:\n\nTraceback (most recent call last):\n  File \"C:\\Users\\aryan\\AppData\\Local\\Programs\\Python\\Python311\\Lib\\site-packages\\urllib3\\connection.py\", line 198, in _new_conn\n    sock = connection.create_connection(\n           ^^^^^^^^^^^^^^^^^^^^^^^^^^^^^\n  File \"C:\\Users\\aryan\\AppData\\Local\\Programs\\Python\\Python311\\Lib\\site-packages\\urllib3\\util\\connection.py\", line 60, in create_connection\n    for res in socket.getaddrinfo(host, port, family, socket.SOCK_STREAM):\n               ^^^^^^^^^^^^^^^^^^^^^^^^^^^^^^^^^^^^^^^^^^^^^^^^^^^^^^^^^^\n  File \"C:\\Users\\aryan\\AppData\\Local\\Programs\\Python\\Python311\\Lib\\socket.py\", line 962, in getaddrinfo\n    for res in _socket.getaddrinfo(host, port, family, type, proto, flags):\n               ^^^^^^^^^^^^^^^^^^^^^^^^^^^^^^^^^^^^^^^^^^^^^^^^^^^^^^^^^^^\nsocket.gaierror: [Errno 11001] getaddrinfo failed\n\nThe above exception was the direct cause of the following exception:\n\nTraceback (most recent call last):\n  File \"C:\\Users\\aryan\\AppData\\Local\\Programs\\Python\\Python311\\Lib\\site-packages\\urllib3\\connectionpool.py\", line 793, in urlopen\n    response = self._make_request(\n               ^^^^^^^^^^^^^^^^^^^\n  File \"C:\\Users\\aryan\\AppData\\Local\\Programs\\Python\\Python311\\Lib\\site-packages\\urllib3\\connectionpool.py\", line 491, in _make_request\n    raise new_e\n  File \"C:\\Users\\aryan\\AppData\\Local\\Programs\\Python\\Python311\\Lib\\site-packages\\urllib3\\connectionpool.py\", line 467, in _make_request\n    self._validate_conn(conn)\n  File \"C:\\Users\\aryan\\AppData\\Local\\Programs\\Python\\Python311\\Lib\\site-packages\\urllib3\\connectionpool.py\", line 1099, in _validate_conn\n    conn.connect()\n  File \"C:\\Users\\aryan\\AppData\\Local\\Programs\\Python\\Python311\\Lib\\site-packages\\urllib3\\connection.py\", line 616, in connect\n    self.sock = sock = self._new_conn()\n                       ^^^^^^^^^^^^^^^^\n  File \"C:\\Users\\aryan\\AppData\\Local\\Programs\\Python\\Python311\\Lib\\site-packages\\urllib3\\connection.py\", line 205, in _new_conn\n    raise NameResolutionError(self.host, self, e) from e\nurllib3.exceptions.NameResolutionError: <urllib3.connection.HTTPSConnection object at 0x00000274A3EAC0D0>: Failed to resolve 'api-t1.fyers.in' ([Errno 11001] getaddrinfo failed)\n\nThe above exception was the direct cause of the following exception:\n\nTraceback (most recent call last):\n  File \"C:\\Users\\aryan\\AppData\\Local\\Programs\\Python\\Python311\\Lib\\site-packages\\requests\\adapters.py\", line 486, in send\n    resp = conn.urlopen(\n           ^^^^^^^^^^^^^\n  File \"C:\\Users\\aryan\\AppData\\Local\\Programs\\Python\\Python311\\Lib\\site-packages\\urllib3\\connectionpool.py\", line 847, in urlopen\n    retries = retries.increment(\n              ^^^^^^^^^^^^^^^^^^\n  File \"C:\\Users\\aryan\\AppData\\Local\\Programs\\Python\\Python311\\Lib\\site-packages\\urllib3\\util\\retry.py\", line 515, in increment\n    raise MaxRetryError(_pool, url, reason) from reason  # type: ignore[arg-type]\n    ^^^^^^^^^^^^^^^^^^^^^^^^^^^^^^^^^^^^^^^^^^^^^^^^^^^\nurllib3.exceptions.MaxRetryError: HTTPSConnectionPool(host='api-t1.fyers.in', port=443): Max retries exceeded with url: /data/symbol-token (Caused by NameResolutionError(\"<urllib3.connection.HTTPSConnection object at 0x00000274A3EAC0D0>: Failed to resolve 'api-t1.fyers.in' ([Errno 11001] getaddrinfo failed)\"))\n\nDuring handling of the above exception, another exception occurred:\n\nTraceback (most recent call last):\n  File \"C:\\Users\\aryan\\AppData\\Local\\Programs\\Python\\Python311\\Lib\\site-packages\\fyers_apiv3\\FyersWebsocket\\data_ws.py\", line 63, in symbol_to_hsmtoken\n    response = requests.post(\n               ^^^^^^^^^^^^^^\n  File \"C:\\Users\\aryan\\AppData\\Local\\Programs\\Python\\Python311\\Lib\\site-packages\\requests\\api.py\", line 115, in post\n    return request(\"post\", url, data=data, json=json, **kwargs)\n           ^^^^^^^^^^^^^^^^^^^^^^^^^^^^^^^^^^^^^^^^^^^^^^^^^^^^\n  File \"C:\\Users\\aryan\\AppData\\Local\\Programs\\Python\\Python311\\Lib\\site-packages\\requests\\api.py\", line 59, in request\n    return session.request(method=method, url=url, **kwargs)\n           ^^^^^^^^^^^^^^^^^^^^^^^^^^^^^^^^^^^^^^^^^^^^^^^^^\n  File \"C:\\Users\\aryan\\AppData\\Local\\Programs\\Python\\Python311\\Lib\\site-packages\\requests\\sessions.py\", line 589, in request\n    resp = self.send(prep, **send_kwargs)\n           ^^^^^^^^^^^^^^^^^^^^^^^^^^^^^^\n  File \"C:\\Users\\aryan\\AppData\\Local\\Programs\\Python\\Python311\\Lib\\site-packages\\requests\\sessions.py\", line 703, in send\n    r = adapter.send(request, **kwargs)\n        ^^^^^^^^^^^^^^^^^^^^^^^^^^^^^^^\n  File \"C:\\Users\\aryan\\AppData\\Local\\Programs\\Python\\Python311\\Lib\\site-packages\\requests\\adapters.py\", line 519, in send\n    raise ConnectionError(e, request=request)\nrequests.exceptions.ConnectionError: HTTPSConnectionPool(host='api-t1.fyers.in', port=443): Max retries exceeded with url: /data/symbol-token (Caused by NameResolutionError(\"<urllib3.connection.HTTPSConnection object at 0x00000274A3EAC0D0>: Failed to resolve 'api-t1.fyers.in' ([Errno 11001] getaddrinfo failed)\"))","exception_name":"ConnectionError"}
{"level":"ERROR","location":"[__symbol_conversion:1375] data_ws","message":"'NoneType' object is not subscriptable","timestamp":"2024-05-15 02:19:04,720+0530","service":"FyersDataSocket","exception":"Traceback (most recent call last):\n  File \"C:\\Users\\aryan\\AppData\\Local\\Programs\\Python\\Python311\\Lib\\site-packages\\websocket\\_app.py\", line 428, in setSock\n    dispatcher.read(self.sock.sock, read, check)\n  File \"C:\\Users\\aryan\\AppData\\Local\\Programs\\Python\\Python311\\Lib\\site-packages\\websocket\\_app.py\", line 99, in read\n    if not read_callback():\n           ^^^^^^^^^^^^^^^\n  File \"C:\\Users\\aryan\\AppData\\Local\\Programs\\Python\\Python311\\Lib\\site-packages\\websocket\\_app.py\", line 442, in read\n    raise e\n  File \"C:\\Users\\aryan\\AppData\\Local\\Programs\\Python\\Python311\\Lib\\site-packages\\websocket\\_app.py\", line 437, in read\n    op_code, frame = self.sock.recv_data_frame(True)\n                     ^^^^^^^^^^^^^^^^^^^^^^^^^^^^^^^\n  File \"C:\\Users\\aryan\\AppData\\Local\\Programs\\Python\\Python311\\Lib\\site-packages\\websocket\\_core.py\", line 406, in recv_data_frame\n    frame = self.recv_frame()\n            ^^^^^^^^^^^^^^^^^\n  File \"C:\\Users\\aryan\\AppData\\Local\\Programs\\Python\\Python311\\Lib\\site-packages\\websocket\\_core.py\", line 445, in recv_frame\n    return self.frame_buffer.recv_frame()\n           ^^^^^^^^^^^^^^^^^^^^^^^^^^^^^^\n  File \"C:\\Users\\aryan\\AppData\\Local\\Programs\\Python\\Python311\\Lib\\site-packages\\websocket\\_abnf.py\", line 338, in recv_frame\n    self.recv_header()\n  File \"C:\\Users\\aryan\\AppData\\Local\\Programs\\Python\\Python311\\Lib\\site-packages\\websocket\\_abnf.py\", line 294, in recv_header\n    header = self.recv_strict(2)\n             ^^^^^^^^^^^^^^^^^^^\n  File \"C:\\Users\\aryan\\AppData\\Local\\Programs\\Python\\Python311\\Lib\\site-packages\\websocket\\_abnf.py\", line 373, in recv_strict\n    bytes_ = self.recv(min(16384, shortage))\n             ^^^^^^^^^^^^^^^^^^^^^^^^^^^^^^^\n  File \"C:\\Users\\aryan\\AppData\\Local\\Programs\\Python\\Python311\\Lib\\site-packages\\websocket\\_core.py\", line 529, in _recv\n    return recv(self.sock, bufsize)\n           ^^^^^^^^^^^^^^^^^^^^^^^^\n  File \"C:\\Users\\aryan\\AppData\\Local\\Programs\\Python\\Python311\\Lib\\site-packages\\websocket\\_socket.py\", line 122, in recv\n    raise WebSocketConnectionClosedException(\nwebsocket._exceptions.WebSocketConnectionClosedException: Connection to remote host was lost.\n\nDuring handling of the above exception, another exception occurred:\n\nTraceback (most recent call last):\n  File \"C:\\Users\\aryan\\AppData\\Local\\Programs\\Python\\Python311\\Lib\\site-packages\\fyers_apiv3\\FyersWebsocket\\data_ws.py\", line 1334, in __symbol_conversion\n    if symbol_value[3] != \"\":\n       ~~~~~~~~~~~~^^^\nTypeError: 'NoneType' object is not subscriptable","exception_name":"TypeError"}
{"level":"ERROR","location":"[symbol_to_hsmtoken:127] data_ws","message":"HTTPSConnectionPool(host='api-t1.fyers.in', port=443): Max retries exceeded with url: /data/symbol-token (Caused by NameResolutionError(\"<urllib3.connection.HTTPSConnection object at 0x00000274A3F49790>: Failed to resolve 'api-t1.fyers.in' ([Errno 11001] getaddrinfo failed)\"))","timestamp":"2024-05-15 02:19:09,676+0530","service":"FyersDataSocket","exception":"Traceback (most recent call last):\n  File \"C:\\Users\\aryan\\AppData\\Local\\Programs\\Python\\Python311\\Lib\\site-packages\\websocket\\_http.py\", line 155, in _get_addrinfo_list\n    addrinfo_list = socket.getaddrinfo(\n                    ^^^^^^^^^^^^^^^^^^^\n  File \"C:\\Users\\aryan\\AppData\\Local\\Programs\\Python\\Python311\\Lib\\socket.py\", line 962, in getaddrinfo\n    for res in _socket.getaddrinfo(host, port, family, type, proto, flags):\n               ^^^^^^^^^^^^^^^^^^^^^^^^^^^^^^^^^^^^^^^^^^^^^^^^^^^^^^^^^^^\nsocket.gaierror: [Errno 11001] getaddrinfo failed\n\nDuring handling of the above exception, another exception occurred:\n\nTraceback (most recent call last):\n  File \"C:\\Users\\aryan\\AppData\\Local\\Programs\\Python\\Python311\\Lib\\site-packages\\websocket\\_app.py\", line 412, in setSock\n    self.sock.connect(\n  File \"C:\\Users\\aryan\\AppData\\Local\\Programs\\Python\\Python311\\Lib\\site-packages\\websocket\\_core.py\", line 249, in connect\n    self.sock, addrs = connect(url, self.sock_opt, proxy_info(**options),\n                       ^^^^^^^^^^^^^^^^^^^^^^^^^^^^^^^^^^^^^^^^^^^^^^^^^^\n  File \"C:\\Users\\aryan\\AppData\\Local\\Programs\\Python\\Python311\\Lib\\site-packages\\websocket\\_http.py\", line 122, in connect\n    addrinfo_list, need_tunnel, auth = _get_addrinfo_list(\n                                       ^^^^^^^^^^^^^^^^^^^\n  File \"C:\\Users\\aryan\\AppData\\Local\\Programs\\Python\\Python311\\Lib\\site-packages\\websocket\\_http.py\", line 167, in _get_addrinfo_list\n    raise WebSocketAddressException(e)\nwebsocket._exceptions.WebSocketAddressException: [Errno 11001] getaddrinfo failed\n\nDuring handling of the above exception, another exception occurred:\n\nTraceback (most recent call last):\n  File \"C:\\Users\\aryan\\AppData\\Local\\Programs\\Python\\Python311\\Lib\\site-packages\\urllib3\\connection.py\", line 198, in _new_conn\n    sock = connection.create_connection(\n           ^^^^^^^^^^^^^^^^^^^^^^^^^^^^^\n  File \"C:\\Users\\aryan\\AppData\\Local\\Programs\\Python\\Python311\\Lib\\site-packages\\urllib3\\util\\connection.py\", line 60, in create_connection\n    for res in socket.getaddrinfo(host, port, family, socket.SOCK_STREAM):\n               ^^^^^^^^^^^^^^^^^^^^^^^^^^^^^^^^^^^^^^^^^^^^^^^^^^^^^^^^^^\n  File \"C:\\Users\\aryan\\AppData\\Local\\Programs\\Python\\Python311\\Lib\\socket.py\", line 962, in getaddrinfo\n    for res in _socket.getaddrinfo(host, port, family, type, proto, flags):\n               ^^^^^^^^^^^^^^^^^^^^^^^^^^^^^^^^^^^^^^^^^^^^^^^^^^^^^^^^^^^\nsocket.gaierror: [Errno 11001] getaddrinfo failed\n\nThe above exception was the direct cause of the following exception:\n\nTraceback (most recent call last):\n  File \"C:\\Users\\aryan\\AppData\\Local\\Programs\\Python\\Python311\\Lib\\site-packages\\urllib3\\connectionpool.py\", line 793, in urlopen\n    response = self._make_request(\n               ^^^^^^^^^^^^^^^^^^^\n  File \"C:\\Users\\aryan\\AppData\\Local\\Programs\\Python\\Python311\\Lib\\site-packages\\urllib3\\connectionpool.py\", line 491, in _make_request\n    raise new_e\n  File \"C:\\Users\\aryan\\AppData\\Local\\Programs\\Python\\Python311\\Lib\\site-packages\\urllib3\\connectionpool.py\", line 467, in _make_request\n    self._validate_conn(conn)\n  File \"C:\\Users\\aryan\\AppData\\Local\\Programs\\Python\\Python311\\Lib\\site-packages\\urllib3\\connectionpool.py\", line 1099, in _validate_conn\n    conn.connect()\n  File \"C:\\Users\\aryan\\AppData\\Local\\Programs\\Python\\Python311\\Lib\\site-packages\\urllib3\\connection.py\", line 616, in connect\n    self.sock = sock = self._new_conn()\n                       ^^^^^^^^^^^^^^^^\n  File \"C:\\Users\\aryan\\AppData\\Local\\Programs\\Python\\Python311\\Lib\\site-packages\\urllib3\\connection.py\", line 205, in _new_conn\n    raise NameResolutionError(self.host, self, e) from e\nurllib3.exceptions.NameResolutionError: <urllib3.connection.HTTPSConnection object at 0x00000274A3F49790>: Failed to resolve 'api-t1.fyers.in' ([Errno 11001] getaddrinfo failed)\n\nThe above exception was the direct cause of the following exception:\n\nTraceback (most recent call last):\n  File \"C:\\Users\\aryan\\AppData\\Local\\Programs\\Python\\Python311\\Lib\\site-packages\\requests\\adapters.py\", line 486, in send\n    resp = conn.urlopen(\n           ^^^^^^^^^^^^^\n  File \"C:\\Users\\aryan\\AppData\\Local\\Programs\\Python\\Python311\\Lib\\site-packages\\urllib3\\connectionpool.py\", line 847, in urlopen\n    retries = retries.increment(\n              ^^^^^^^^^^^^^^^^^^\n  File \"C:\\Users\\aryan\\AppData\\Local\\Programs\\Python\\Python311\\Lib\\site-packages\\urllib3\\util\\retry.py\", line 515, in increment\n    raise MaxRetryError(_pool, url, reason) from reason  # type: ignore[arg-type]\n    ^^^^^^^^^^^^^^^^^^^^^^^^^^^^^^^^^^^^^^^^^^^^^^^^^^^\nurllib3.exceptions.MaxRetryError: HTTPSConnectionPool(host='api-t1.fyers.in', port=443): Max retries exceeded with url: /data/symbol-token (Caused by NameResolutionError(\"<urllib3.connection.HTTPSConnection object at 0x00000274A3F49790>: Failed to resolve 'api-t1.fyers.in' ([Errno 11001] getaddrinfo failed)\"))\n\nDuring handling of the above exception, another exception occurred:\n\nTraceback (most recent call last):\n  File \"C:\\Users\\aryan\\AppData\\Local\\Programs\\Python\\Python311\\Lib\\site-packages\\fyers_apiv3\\FyersWebsocket\\data_ws.py\", line 63, in symbol_to_hsmtoken\n    response = requests.post(\n               ^^^^^^^^^^^^^^\n  File \"C:\\Users\\aryan\\AppData\\Local\\Programs\\Python\\Python311\\Lib\\site-packages\\requests\\api.py\", line 115, in post\n    return request(\"post\", url, data=data, json=json, **kwargs)\n           ^^^^^^^^^^^^^^^^^^^^^^^^^^^^^^^^^^^^^^^^^^^^^^^^^^^^\n  File \"C:\\Users\\aryan\\AppData\\Local\\Programs\\Python\\Python311\\Lib\\site-packages\\requests\\api.py\", line 59, in request\n    return session.request(method=method, url=url, **kwargs)\n           ^^^^^^^^^^^^^^^^^^^^^^^^^^^^^^^^^^^^^^^^^^^^^^^^^\n  File \"C:\\Users\\aryan\\AppData\\Local\\Programs\\Python\\Python311\\Lib\\site-packages\\requests\\sessions.py\", line 589, in request\n    resp = self.send(prep, **send_kwargs)\n           ^^^^^^^^^^^^^^^^^^^^^^^^^^^^^^\n  File \"C:\\Users\\aryan\\AppData\\Local\\Programs\\Python\\Python311\\Lib\\site-packages\\requests\\sessions.py\", line 703, in send\n    r = adapter.send(request, **kwargs)\n        ^^^^^^^^^^^^^^^^^^^^^^^^^^^^^^^\n  File \"C:\\Users\\aryan\\AppData\\Local\\Programs\\Python\\Python311\\Lib\\site-packages\\requests\\adapters.py\", line 519, in send\n    raise ConnectionError(e, request=request)\nrequests.exceptions.ConnectionError: HTTPSConnectionPool(host='api-t1.fyers.in', port=443): Max retries exceeded with url: /data/symbol-token (Caused by NameResolutionError(\"<urllib3.connection.HTTPSConnection object at 0x00000274A3F49790>: Failed to resolve 'api-t1.fyers.in' ([Errno 11001] getaddrinfo failed)\"))","exception_name":"ConnectionError"}
{"level":"ERROR","location":"[__symbol_conversion:1375] data_ws","message":"'NoneType' object is not subscriptable","timestamp":"2024-05-15 02:19:09,691+0530","service":"FyersDataSocket","exception":"Traceback (most recent call last):\n  File \"C:\\Users\\aryan\\AppData\\Local\\Programs\\Python\\Python311\\Lib\\site-packages\\websocket\\_http.py\", line 155, in _get_addrinfo_list\n    addrinfo_list = socket.getaddrinfo(\n                    ^^^^^^^^^^^^^^^^^^^\n  File \"C:\\Users\\aryan\\AppData\\Local\\Programs\\Python\\Python311\\Lib\\socket.py\", line 962, in getaddrinfo\n    for res in _socket.getaddrinfo(host, port, family, type, proto, flags):\n               ^^^^^^^^^^^^^^^^^^^^^^^^^^^^^^^^^^^^^^^^^^^^^^^^^^^^^^^^^^^\nsocket.gaierror: [Errno 11001] getaddrinfo failed\n\nDuring handling of the above exception, another exception occurred:\n\nTraceback (most recent call last):\n  File \"C:\\Users\\aryan\\AppData\\Local\\Programs\\Python\\Python311\\Lib\\site-packages\\websocket\\_app.py\", line 412, in setSock\n    self.sock.connect(\n  File \"C:\\Users\\aryan\\AppData\\Local\\Programs\\Python\\Python311\\Lib\\site-packages\\websocket\\_core.py\", line 249, in connect\n    self.sock, addrs = connect(url, self.sock_opt, proxy_info(**options),\n                       ^^^^^^^^^^^^^^^^^^^^^^^^^^^^^^^^^^^^^^^^^^^^^^^^^^\n  File \"C:\\Users\\aryan\\AppData\\Local\\Programs\\Python\\Python311\\Lib\\site-packages\\websocket\\_http.py\", line 122, in connect\n    addrinfo_list, need_tunnel, auth = _get_addrinfo_list(\n                                       ^^^^^^^^^^^^^^^^^^^\n  File \"C:\\Users\\aryan\\AppData\\Local\\Programs\\Python\\Python311\\Lib\\site-packages\\websocket\\_http.py\", line 167, in _get_addrinfo_list\n    raise WebSocketAddressException(e)\nwebsocket._exceptions.WebSocketAddressException: [Errno 11001] getaddrinfo failed\n\nDuring handling of the above exception, another exception occurred:\n\nTraceback (most recent call last):\n  File \"C:\\Users\\aryan\\AppData\\Local\\Programs\\Python\\Python311\\Lib\\site-packages\\fyers_apiv3\\FyersWebsocket\\data_ws.py\", line 1334, in __symbol_conversion\n    if symbol_value[3] != \"\":\n       ~~~~~~~~~~~~^^^\nTypeError: 'NoneType' object is not subscriptable","exception_name":"TypeError"}
{"level":"ERROR","location":"[On_message:1443] data_ws","message":"'vol_traded_today'","timestamp":"2024-05-15 02:19:13,998+0530","service":"FyersDataSocket","exception":"Traceback (most recent call last):\n  File \"C:\\Users\\aryan\\AppData\\Local\\Programs\\Python\\Python311\\Lib\\site-packages\\fyers_apiv3\\FyersWebsocket\\data_ws.py\", line 1434, in On_message\n    self.OnMessage(message)\n  File \"c:\\Users\\aryan\\Desktop\\FYRES\\socket_dat.py\", line 21, in onmessage\n    vol=message['vol_traded_today']\n        ~~~~~~~^^^^^^^^^^^^^^^^^^^^\nKeyError: 'vol_traded_today'","exception_name":"KeyError"}
{"level":"ERROR","location":"[On_message:1443] data_ws","message":"'vol_traded_today'","timestamp":"2024-05-15 02:19:14,744+0530","service":"FyersDataSocket","exception":"Traceback (most recent call last):\n  File \"C:\\Users\\aryan\\AppData\\Local\\Programs\\Python\\Python311\\Lib\\site-packages\\fyers_apiv3\\FyersWebsocket\\data_ws.py\", line 1434, in On_message\n    self.OnMessage(message)\n  File \"c:\\Users\\aryan\\Desktop\\FYRES\\socket_dat.py\", line 21, in onmessage\n    vol=message['vol_traded_today']\n        ~~~~~~~^^^^^^^^^^^^^^^^^^^^\nKeyError: 'vol_traded_today'","exception_name":"KeyError"}
{"level":"ERROR","location":"[On_message:1443] data_ws","message":"'vol_traded_today'","timestamp":"2024-05-15 02:19:15,770+0530","service":"FyersDataSocket","exception":"Traceback (most recent call last):\n  File \"C:\\Users\\aryan\\AppData\\Local\\Programs\\Python\\Python311\\Lib\\site-packages\\fyers_apiv3\\FyersWebsocket\\data_ws.py\", line 1434, in On_message\n    self.OnMessage(message)\n  File \"c:\\Users\\aryan\\Desktop\\FYRES\\socket_dat.py\", line 21, in onmessage\n    vol=message['vol_traded_today']\n        ~~~~~~~^^^^^^^^^^^^^^^^^^^^\nKeyError: 'vol_traded_today'","exception_name":"KeyError"}
{"level":"ERROR","location":"[On_message:1443] data_ws","message":"'vol_traded_today'","timestamp":"2024-05-15 02:19:15,812+0530","service":"FyersDataSocket","exception":"Traceback (most recent call last):\n  File \"C:\\Users\\aryan\\AppData\\Local\\Programs\\Python\\Python311\\Lib\\site-packages\\fyers_apiv3\\FyersWebsocket\\data_ws.py\", line 1434, in On_message\n    self.OnMessage(message)\n  File \"c:\\Users\\aryan\\Desktop\\FYRES\\socket_dat.py\", line 21, in onmessage\n    vol=message['vol_traded_today']\n        ~~~~~~~^^^^^^^^^^^^^^^^^^^^\nKeyError: 'vol_traded_today'","exception_name":"KeyError"}
{"level":"ERROR","location":"[On_message:1443] data_ws","message":"'vol_traded_today'","timestamp":"2024-05-15 02:52:33,911+0530","service":"FyersDataSocket","exception":"Traceback (most recent call last):\n  File \"C:\\Users\\aryan\\AppData\\Local\\Programs\\Python\\Python311\\Lib\\site-packages\\fyers_apiv3\\FyersWebsocket\\data_ws.py\", line 1434, in On_message\n    self.OnMessage(message)\n  File \"c:\\Users\\aryan\\Desktop\\FYRES\\socket_dat.py\", line 21, in onmessage\n    vol=message['vol_traded_today']\n        ~~~~~~~^^^^^^^^^^^^^^^^^^^^\nKeyError: 'vol_traded_today'","exception_name":"KeyError"}
{"level":"ERROR","location":"[On_message:1443] data_ws","message":"'vol_traded_today'","timestamp":"2024-05-15 02:52:34,531+0530","service":"FyersDataSocket","exception":"Traceback (most recent call last):\n  File \"C:\\Users\\aryan\\AppData\\Local\\Programs\\Python\\Python311\\Lib\\site-packages\\fyers_apiv3\\FyersWebsocket\\data_ws.py\", line 1434, in On_message\n    self.OnMessage(message)\n  File \"c:\\Users\\aryan\\Desktop\\FYRES\\socket_dat.py\", line 21, in onmessage\n    vol=message['vol_traded_today']\n        ~~~~~~~^^^^^^^^^^^^^^^^^^^^\nKeyError: 'vol_traded_today'","exception_name":"KeyError"}
{"level":"ERROR","location":"[On_message:1443] data_ws","message":"'vol_traded_today'","timestamp":"2024-05-15 02:52:34,697+0530","service":"FyersDataSocket","exception":"Traceback (most recent call last):\n  File \"C:\\Users\\aryan\\AppData\\Local\\Programs\\Python\\Python311\\Lib\\site-packages\\fyers_apiv3\\FyersWebsocket\\data_ws.py\", line 1434, in On_message\n    self.OnMessage(message)\n  File \"c:\\Users\\aryan\\Desktop\\FYRES\\socket_dat.py\", line 21, in onmessage\n    vol=message['vol_traded_today']\n        ~~~~~~~^^^^^^^^^^^^^^^^^^^^\nKeyError: 'vol_traded_today'","exception_name":"KeyError"}
{"level":"ERROR","location":"[On_message:1443] data_ws","message":"'vol_traded_today'","timestamp":"2024-05-15 02:52:34,846+0530","service":"FyersDataSocket","exception":"Traceback (most recent call last):\n  File \"C:\\Users\\aryan\\AppData\\Local\\Programs\\Python\\Python311\\Lib\\site-packages\\fyers_apiv3\\FyersWebsocket\\data_ws.py\", line 1434, in On_message\n    self.OnMessage(message)\n  File \"c:\\Users\\aryan\\Desktop\\FYRES\\socket_dat.py\", line 21, in onmessage\n    vol=message['vol_traded_today']\n        ~~~~~~~^^^^^^^^^^^^^^^^^^^^\nKeyError: 'vol_traded_today'","exception_name":"KeyError"}
